<!--
s-model_finder_articulated_macro(prefix)

Creates an articulated s-model finder with the passed in prefix.  The
prefix typcially includes the hand prefix and an identifier for the
finger(i.e. finger_1, etc...).

-->
<robot xmlns:xacro="http://ros.org/wiki/xacro">
	<xacro:macro name="s-model_finger_articulated" params="prefix">
		<!-- link list -->
		<link name="${prefix}_link_0">
			<visual>
				<origin xyz="0.020 0 0" rpy="0 0 0"/>
				<geometry>
					<mesh filename="package://robotiq_s_model_visualization/meshes/s-model_articulated/visual/link_0.STL" />
				</geometry>
				<material name="green">
					<color rgba="0 1 0 1"/>
				</material>
			</visual>
			<collision>	
				<origin xyz="-0.0455 0.0414 0.036" rpy="0 3.1416 -1.57"/>
				<geometry>
					<mesh filename="package://robotiq_s_model_visualization/meshes/s-model_articulated/collision/link_0_low_poly.STL" />
				</geometry>
				<material name="yellow">
					<color rgba="0 1 1 1"/>
				</material>
			</collision>
            <inertial>
                <origin xyz="0 0 0" rpy="0 0 0"/>
                <mass value="0.083"/>
                <inertia ixx="0.01" ixy="-0.00002" ixz="0.00001" iyy="0.0008" iyz="0" izz="0.001" />
            </inertial>         
		</link>
		<link name="${prefix}_link_1">
			<visual>
				<origin xyz="0.050 -.028 0" rpy="0 0 -0.52"/>
				<geometry>
					<mesh filename="package://robotiq_s_model_visualization/meshes/s-model_articulated/visual/link_1.STL" />
				</geometry>
				<material name="green"/>
			</visual>
			<collision>
				<origin xyz="0.050 -.028 0" rpy="0 0 -0.52"/>
				<geometry>
					<mesh filename="package://robotiq_s_model_visualization/meshes/s-model_articulated/collision/link_1_low_poly.STL" />
				</geometry>
				<material name="yellow"/>
			</collision>
            <inertial>
                <origin xyz="0 0 0" rpy="0 0 0"/>
                <mass value="0.083"/>
                <inertia ixx="0.001859" ixy="-0.000376" ixz="0.000028" iyy="0.012756" iyz="0" izz="0.0024" />
            </inertial>
		</link>
		<link name="${prefix}_link_2">
			<!--
			NOTE: This link has an offset in the z-direction based on the models that were
			used to generate grap-it poses.  With the offset below the model appears visually
			correct, but it is suspect.
			-->
			<visual>
				<origin xyz="0.039 0 0.0075" rpy="0 0 0"/>
				<geometry>
					<mesh filename="package://robotiq_s_model_visualization/meshes/s-model_articulated/visual/link_2.STL" />
				</geometry>
				<material name="green"/>
			</visual>
			<collision>
				<origin xyz="0.039 0 0.0075" rpy="0 0 0"/>
				<geometry>
					<mesh filename="package://robotiq_s_model_visualization/meshes/s-model_articulated/collision/link_2_low_poly.STL" />
				</geometry>
				<material name="yellow"/>
			</collision>
            <inertial>
                <origin xyz="0 0 0" rpy="0 0 0"/>
                <mass value="0.083"/>
                <inertia ixx="0.001859" ixy="-0.000376" ixz="0.000028" iyy="0.012756" iyz="0" izz="0.0024" />
            </inertial>
		</link>
		<link name="${prefix}_link_3">
			<visual>
				<origin xyz="0 0 0" rpy="0 0 0.52"/>
				<geometry>
					<mesh filename="package://robotiq_s_model_visualization/meshes/s-model_articulated/visual/link_3.STL" />
				</geometry>
				<material name="green"/>
			</visual>
			<collision>
				<origin xyz="0 0 0" rpy="0 0 0.52"/>
				<geometry>
					<mesh filename="package://robotiq_s_model_visualization/meshes/s-model_articulated/collision/link_3_low_poly.STL" />
				</geometry>
				<material name="yellow"/>
			</collision>
            <inertial>
                <origin xyz="0 0 0" rpy="0 0 0"/>
                <mass value="0.083"/>
                <inertia ixx="0.001239" ixy="-0.000251" ixz="0.000019" iyy="0.00085" iyz="0" izz="0.001632" />
            </inertial>
		</link>

		<!-- end of link list -->
		<!-- joint list -->
		
		<!-- WARNING: LIMITS NOT CORRECT -->
		<joint name="${prefix}_j1" type="revolute">
			<parent link="${prefix}_link_0"/>
			<child link="${prefix}_link_1"/>
			<axis xyz="0 0 1"/>
			<origin xyz="0.020 0 0" rpy="0 0 0"/>
			<limit lower="0" upper="1.22" effort="100" velocity="100"/>
		</joint>
		<!-- WARNING: LIMITS NOT CORRECT -->
		<joint name="${prefix}_j2" type="revolute">
			<parent link="${prefix}_link_1"/>
			<child link="${prefix}_link_2"/>
			<axis xyz="0 0 1"/>
			<origin xyz="0.050 -.028 0" rpy="0 0 -0.52"/>
			<limit lower="0" upper="1.22" effort="100" velocity="100"/>
                        <mimic joint="${prefix}_j1" multiplier="0.5" offset="0"/>
		</joint>
		<!-- WARNING: LIMITS NOT CORRECT -->
		<joint name="${prefix}_j3" type="revolute">
			<parent link="${prefix}_link_2"/>
			<child link="${prefix}_link_3"/>
			<axis xyz="0 0 1"/>
			<origin xyz="0.039 0 0" rpy="0 0 0"/>
			<limit lower="0" upper="1.22" effort="100" velocity="100"/>
                        <mimic joint="${prefix}_j1" multiplier="0.5" offset="0"/>
		</joint>
		<!-- end of joint list -->
	</xacro:macro>
</robot>
