<!--
s-model_articulated_macro(prefix)

Creates an articulated s-model hand with the passed in prefix.  If there
is only one hand in the urdf then an empty prefix can be used "".  If
there are multiple hands then a prefix followed by an "_" is needed.

-->
<robot xmlns:xacro="http://ros.org/wiki/xacro">
        <xacro:include filename="$(find vigir_atlas_addons_description)/robots/flor_robotiq_finger.urdf.xacro" />

	<xacro:macro name="s-model_articulated_with_poking_stick" params="prefix parent *origin">
	<xacro:s-model_finger_articulated prefix="${prefix}_f1"/>
	<xacro:s-model_finger_articulated prefix="${prefix}_f2"/>
	<xacro:s-model_finger_articulated prefix="${prefix}_f0"/>

	<!-- Joint to connect with robot parent-->
	<joint name="${prefix}_robotiq_hand_joint" type="fixed">
		<parent link="${parent}"/>
		<child link="${prefix}_palm"/>
		<insert_block name="origin" />
	</joint>	
		<!-- link list -->
		<link name="${prefix}_palm">
			<visual>
				<geometry>
					<mesh filename="package://robotiq_s_model_visualization/meshes/s-model_articulated/visual/palm.STL" />
				</geometry>
				<material name="green">
					<color rgba="0 1 0 1"/>
				</material>
			</visual>
			<collision>
				<geometry>
					<mesh filename="package://robotiq_s_model_visualization/meshes/s-model_articulated/collision/palm_low_poly.STL" />
				</geometry>
				<material name="yellow">
					<color rgba="0 1 1 1"/>
				</material>
			</collision>
			<collision>
                                <geometry>
                                        <box size="0.17 0.05 0.17" />
                                </geometry>
                                <material name="yellow">
                                        <color rgba="0 1 1 1"/>
                                </material>
                        </collision>
			
                        <!--<xacro:hand_guard_collision_macro />-->
                        <collision>
                                <origin xyz="0 -0.07 0" rpy="0 -1.57 0"/>
                                <geometry>

                                       <!--<mesh filename="package://vigir_atlas_addons_description/meshes/side_peg_guard.stl" />-->
                                       <box size="0.15 0.025 0.15" />
                                </geometry>
                                <material name="yellow">
                                        <color rgba="0 1 1 1"/>
                                </material>
                        </collision>
                        <collision>
                                <origin xyz="0.0 -0.07 0.114" rpy="0 -1.57 0"/>
                                <geometry>

                                       <!--<mesh filename="package://vigir_atlas_addons_description/meshes/side_peg_guard.stl" />-->
                                       <box size="0.15 0.025 0.025" />
                                </geometry>
                                <material name="yellow">
                                        <color rgba="0 1 1 1"/>
                                </material>
                        </collision>
                        
                        <visual>
                                <origin xyz="0 -0.08 0" rpy="0 -1.57 0"/>
                                <geometry>

                                       <mesh filename="package://vigir_atlas_addons_description/meshes/side_peg_guard.stl" />
                                       <!--<box size="0.17 0.05 0.17" />-->
                                </geometry>
                                <material name="yellow">
                                        <color rgba="0 1 1 1"/>
                                </material>
                        </visual>
                        
                        <collision>
                                <geometry>
                                        <box size="0.17 0.05 0.17" />
                                </geometry>
                                <material name="yellow">
                                        <color rgba="0 1 1 1"/>
                                </material>
                        </collision>
	                
	                <inertial>
                          <origin xyz="0 0 0" rpy="0 0 0"/>
                          <mass value="1.3"/>
                          <inertia ixx="0.006012" ixy="0.000079" ixz="-0.00024" iyy="0.012892" iyz="0" izz="0.002435" />
                        </inertial>
		</link>
        

		<!-- end of link list -->
		<!-- joint list -->

		<!-- WARNING: LIMITS NOT CORRECT -->
		<joint name="${prefix}_f1_j0" type="revolute">
			<parent link="${prefix}_palm"/>
			<child link="${prefix}_f1_link_0"/>
			<axis xyz="0 -1 0"/>
			<origin xyz="-0.0455 0.0214 0.036" rpy="0 3.1416 -1.57"/>
			<limit lower="-0.13" upper="0.15" effort="100" velocity="100"/>
		</joint>
		<!-- WARNING: LIMITS NOT CORRECT -->
		<joint name="${prefix}_f2_j0" type="revolute">
			<parent link="${prefix}_palm"/>
			<child link="${prefix}_f2_link_0"/>
			<axis xyz="0 -1 0"/>
			<origin xyz="-0.0455 0.0214 -0.036" rpy="0 3.1416 -1.57"/>
			<limit lower="-0.15" upper="0.13" effort="100" velocity="100"/>
                        <mimic joint="${prefix}_f1_j0" multiplier="-1" offset="0"/>
		</joint>
		<joint name="${prefix}_f0_j0" type="fixed">
			<parent link="${prefix}_palm"/>
			<child link="${prefix}_f0_link_0"/>
			<axis xyz="0 0 1"/>
			<origin xyz="0.0455 0.0214 0" rpy="0 0 1.57"/>
		</joint>
		<!-- end of joint list -->
	</xacro:macro>
</robot>
